Traceback (most recent call last):
  File "/usr/local/lib/python3.8/site-packages/jupyter_cache/executors/utils.py", line 51, in single_nb_execution
    executenb(
  File "/usr/local/lib/python3.8/site-packages/nbclient/client.py", line 1087, in execute
    return NotebookClient(nb=nb, resources=resources, km=km, **kwargs).execute()
  File "/usr/local/lib/python3.8/site-packages/nbclient/util.py", line 74, in wrapped
    return just_run(coro(*args, **kwargs))
  File "/usr/local/lib/python3.8/site-packages/nbclient/util.py", line 53, in just_run
    return loop.run_until_complete(coro)
  File "/usr/local/Cellar/python@3.8/3.8.11/Frameworks/Python.framework/Versions/3.8/lib/python3.8/asyncio/base_events.py", line 616, in run_until_complete
    return future.result()
  File "/usr/local/lib/python3.8/site-packages/nbclient/client.py", line 540, in async_execute
    await self.async_execute_cell(
  File "/usr/local/lib/python3.8/site-packages/nbclient/client.py", line 832, in async_execute_cell
    self._check_raise_for_error(cell, exec_reply)
  File "/usr/local/lib/python3.8/site-packages/nbclient/client.py", line 740, in _check_raise_for_error
    raise CellExecutionError.from_cell_and_msg(cell, exec_reply['content'])
nbclient.exceptions.CellExecutionError: An error occurred while executing the following cell:
------------------
got_df = pd.read_csv('roles_professions.csv')
got_df
G = networkx.from_pandas_edgelist(got_df, 'Source', 'Target','Weight')
------------------

[0;31m---------------------------------------------------------------------------[0m
[0;31mKeyError[0m                                  Traceback (most recent call last)
[0;32m/usr/local/lib/python3.8/site-packages/pandas/core/indexes/base.py[0m in [0;36mget_loc[0;34m(self, key, method, tolerance)[0m
[1;32m   3079[0m             [0;32mtry[0m[0;34m:[0m[0;34m[0m[0;34m[0m[0m
[0;32m-> 3080[0;31m                 [0;32mreturn[0m [0mself[0m[0;34m.[0m[0m_engine[0m[0;34m.[0m[0mget_loc[0m[0;34m([0m[0mcasted_key[0m[0;34m)[0m[0;34m[0m[0;34m[0m[0m
[0m[1;32m   3081[0m             [0;32mexcept[0m [0mKeyError[0m [0;32mas[0m [0merr[0m[0;34m:[0m[0;34m[0m[0;34m[0m[0m

[0;32mpandas/_libs/index.pyx[0m in [0;36mpandas._libs.index.IndexEngine.get_loc[0;34m()[0m

[0;32mpandas/_libs/index.pyx[0m in [0;36mpandas._libs.index.IndexEngine.get_loc[0;34m()[0m

[0;32mpandas/_libs/hashtable_class_helper.pxi[0m in [0;36mpandas._libs.hashtable.PyObjectHashTable.get_item[0;34m()[0m

[0;32mpandas/_libs/hashtable_class_helper.pxi[0m in [0;36mpandas._libs.hashtable.PyObjectHashTable.get_item[0;34m()[0m

[0;31mKeyError[0m: 'Weight'

The above exception was the direct cause of the following exception:

[0;31mKeyError[0m                                  Traceback (most recent call last)
[0;32m/usr/local/lib/python3.8/site-packages/networkx/convert_matrix.py[0m in [0;36mfrom_pandas_edgelist[0;34m(df, source, target, edge_attr, create_using, edge_key)[0m
[1;32m    440[0m     [0;32mtry[0m[0;34m:[0m[0;34m[0m[0;34m[0m[0m
[0;32m--> 441[0;31m         [0mattribute_data[0m [0;34m=[0m [0mzip[0m[0;34m([0m[0;34m*[0m[0;34m[[0m[0mdf[0m[0;34m[[0m[0mcol[0m[0;34m][0m [0;32mfor[0m [0mcol[0m [0;32min[0m [0mattr_col_headings[0m[0;34m][0m[0;34m)[0m[0;34m[0m[0;34m[0m[0m
[0m[1;32m    442[0m     [0;32mexcept[0m [0;34m([0m[0mKeyError[0m[0;34m,[0m [0mTypeError[0m[0;34m)[0m [0;32mas[0m [0me[0m[0;34m:[0m[0;34m[0m[0;34m[0m[0m

[0;32m/usr/local/lib/python3.8/site-packages/networkx/convert_matrix.py[0m in [0;36m<listcomp>[0;34m(.0)[0m
[1;32m    440[0m     [0;32mtry[0m[0;34m:[0m[0;34m[0m[0;34m[0m[0m
[0;32m--> 441[0;31m         [0mattribute_data[0m [0;34m=[0m [0mzip[0m[0;34m([0m[0;34m*[0m[0;34m[[0m[0mdf[0m[0;34m[[0m[0mcol[0m[0;34m][0m [0;32mfor[0m [0mcol[0m [0;32min[0m [0mattr_col_headings[0m[0;34m][0m[0;34m)[0m[0;34m[0m[0;34m[0m[0m
[0m[1;32m    442[0m     [0;32mexcept[0m [0;34m([0m[0mKeyError[0m[0;34m,[0m [0mTypeError[0m[0;34m)[0m [0;32mas[0m [0me[0m[0;34m:[0m[0;34m[0m[0;34m[0m[0m

[0;32m/usr/local/lib/python3.8/site-packages/pandas/core/frame.py[0m in [0;36m__getitem__[0;34m(self, key)[0m
[1;32m   3023[0m                 [0;32mreturn[0m [0mself[0m[0;34m.[0m[0m_getitem_multilevel[0m[0;34m([0m[0mkey[0m[0;34m)[0m[0;34m[0m[0;34m[0m[0m
[0;32m-> 3024[0;31m             [0mindexer[0m [0;34m=[0m [0mself[0m[0;34m.[0m[0mcolumns[0m[0;34m.[0m[0mget_loc[0m[0;34m([0m[0mkey[0m[0;34m)[0m[0;34m[0m[0;34m[0m[0m
[0m[1;32m   3025[0m             [0;32mif[0m [0mis_integer[0m[0;34m([0m[0mindexer[0m[0;34m)[0m[0;34m:[0m[0;34m[0m[0;34m[0m[0m

[0;32m/usr/local/lib/python3.8/site-packages/pandas/core/indexes/base.py[0m in [0;36mget_loc[0;34m(self, key, method, tolerance)[0m
[1;32m   3081[0m             [0;32mexcept[0m [0mKeyError[0m [0;32mas[0m [0merr[0m[0;34m:[0m[0;34m[0m[0;34m[0m[0m
[0;32m-> 3082[0;31m                 [0;32mraise[0m [0mKeyError[0m[0;34m([0m[0mkey[0m[0;34m)[0m [0;32mfrom[0m [0merr[0m[0;34m[0m[0;34m[0m[0m
[0m[1;32m   3083[0m [0;34m[0m[0m

[0;31mKeyError[0m: 'Weight'

The above exception was the direct cause of the following exception:

[0;31mNetworkXError[0m                             Traceback (most recent call last)
[0;32m/var/folders/6n/6jrs9zvs35b405z7ck19fpwm0000gn/T/ipykernel_44736/997027204.py[0m in [0;36m<module>[0;34m[0m
[1;32m      1[0m [0mgot_df[0m [0;34m=[0m [0mpd[0m[0;34m.[0m[0mread_csv[0m[0;34m([0m[0;34m'roles_professions.csv'[0m[0;34m)[0m[0;34m[0m[0;34m[0m[0m
[1;32m      2[0m [0mgot_df[0m[0;34m[0m[0;34m[0m[0m
[0;32m----> 3[0;31m [0mG[0m [0;34m=[0m [0mnetworkx[0m[0;34m.[0m[0mfrom_pandas_edgelist[0m[0;34m([0m[0mgot_df[0m[0;34m,[0m [0;34m'Source'[0m[0;34m,[0m [0;34m'Target'[0m[0;34m,[0m[0;34m'Weight'[0m[0;34m)[0m[0;34m[0m[0;34m[0m[0m
[0m
[0;32m/usr/local/lib/python3.8/site-packages/networkx/convert_matrix.py[0m in [0;36mfrom_pandas_edgelist[0;34m(df, source, target, edge_attr, create_using, edge_key)[0m
[1;32m    442[0m     [0;32mexcept[0m [0;34m([0m[0mKeyError[0m[0;34m,[0m [0mTypeError[0m[0;34m)[0m [0;32mas[0m [0me[0m[0;34m:[0m[0;34m[0m[0;34m[0m[0m
[1;32m    443[0m         [0mmsg[0m [0;34m=[0m [0;34mf"Invalid edge_attr argument: {edge_attr}"[0m[0;34m[0m[0;34m[0m[0m
[0;32m--> 444[0;31m         [0;32mraise[0m [0mnx[0m[0;34m.[0m[0mNetworkXError[0m[0;34m([0m[0mmsg[0m[0;34m)[0m [0;32mfrom[0m [0me[0m[0;34m[0m[0;34m[0m[0m
[0m[1;32m    445[0m [0;34m[0m[0m
[1;32m    446[0m     [0;32mif[0m [0mg[0m[0;34m.[0m[0mis_multigraph[0m[0;34m([0m[0;34m)[0m[0;34m:[0m[0;34m[0m[0;34m[0m[0m

[0;31mNetworkXError[0m: Invalid edge_attr argument: Weight
NetworkXError: Invalid edge_attr argument: Weight

